Workbook
Name RosterNames: Roster!$A$2:$A$40
Name DealCodes: Deals!$A$2:$A$355
Name LifecycleList: Settings!$D$8:$D$16
Name PhaseList: Settings!$E$8:$E$11
Name TxnTypeList: Settings!$F$8:$F$12
Name EntityClassList: Settings!$G$8:$G$11
Name ScopeList: Settings!$H$8:$H$15
Name TimelineList: Settings!$I$8:$I$9
Name ActiveList: Settings!$J$8:$J$9
Name YesNoList: Settings!$K$8:$K$9
Name LevelList: Settings!$L$8:$L$14
Name ArchetypeList: Templates!$A$3:$A$10
Name MapNetSuite: Actuals!$N$5:$N$44
Name MapTracker: Actuals!$O$5:$O$44
Name TddTypeList: Settings!$M$8:$M$12
Name TddScopeList: Settings!$N$8:$N$10
Name OtherTddList: Settings!$O$8:$O$11
Name CorpModelList: Settings!$P$8:$P$9
Name YTickList: Settings!$Q$8:$Q$8

Sheet Guide
B1: US M&A Tax - Scheduling & Capacity Tracker
B2: Built from Scheduling_US_MA_July_9.xlsx + the June 4 scheduling brief. This workbook is the bridge tracker: one source of truth for deals, staffing and weekly capacity.
B4: TABS
B5: Capacity - the dashboard: planned hours per person per week. Red = over capacity, amber = above 85%.
B6: Check-in - the weekly 15-20 min meeting agenda, generated automatically: who's over/under-allocated in the next 4 weeks, and which Active/Proposal deals need attention (unstaffed, missing a staffed level, still at the default probability, no dates, or stale). Nothing to edit here - update Settings!B19 to today first.
B7: Scenario - what-if analysis. Fill the violet SCENARIO columns on Deals (probability / start / end) - e.g. bump three proposals to 100% - and this tab shows who would blow up, Live vs Scenario, without touching the real plan. Blank overrides = identical to Live.
B8: Deals - one row per engagement: lifecycle, probability, dates. The yellow WORKSTREAM SCOPING columns are Justine's taxonomy - tick what's in scope. The yellow FEE $ columns (one per group: TDD, Modeling, Structuring, Legal docs, Other) drive the hours - enter a fee and it flows to hours-by-level through Templates. Violet columns are scenario overrides. (Old attribute columns K-P are retired and hidden.)
B9: Assignments - one row per person on a deal. 'Active?' controls whether it counts. Hours come from the deal's fees (split by level), or its archetype, or the level default - unless you set an Override (Override always wins). Columns N onward ('Eff. start/end', 'Seg1/Seg2 ...', 'Fee hrs/wk pp') are calculation helpers - leave them alone.
B10: Roster - the team, weekly capacity, live utilization.
B11: Templates - the fee->hours allocation parameters: rate card ($/hr by level), fee split-% matrix by workstream group, and default durations. Fill the yellow cells with the team's real numbers; Step 9 wires per-deal fees into hours. (The old effort archetypes above are legacy, kept for reference.)
B12: Actuals - paste the NetSuite time export (blue columns); it matches each row to a deal and person and computes variance vs the plan. Fill the name-mapping table (right) when NetSuite names differ from roster names. Sample rows are included and flagged - delete them first.
B13: Variance - estimate vs actual: per deal, and a calibration summary by level and by archetype (actual/planned ratio - >1 means we estimate low, <1 means high). Reads from Actuals.
... B42: Source: Scheduling_US_MA_July_9.xlsx (July 9) and Justine Morin's scheduling brief (June 4, 2026). Migration by scripts/build_workbook.py - regenerating overwrites manual edits, so edit here, not there.

Sheet Capacity
A1: Capacity - planned hours per person per week
A2: ="Probability weighting: "&Settings!$B$4&" | Fees set on a deal drive its hours, spread evenly across its dates; a deal with an Archetype + dates is front/tail phased instead; a deal with no dates counts flat in every week."
A4: Person | B4: Cap hrs/wk | C4: =Settings!$B$3 | D4: =C4+7 | E4: =D4+7 | F4: =E4+7 | G4: =F4+7 | H4: =G4+7 | I4: =H4+7 | J4: =I4+7 | K4: =J4+7 | ... AB4: =AA4+7
A5: =IF(Roster!$A2="","",Roster!$A2) | B5: =IF($A5="","",IFERROR(INDEX(Roster!$D$2:$D$40,MATCH($A5,Roster!$A$2:$A$40,0)),"")) | C5: =IF($A5="","",SUMIFS(Assignments!$X$2:$X$769,Assignments!$A$2:$A$769,$A5,Assignments!$G$2:$G$769,"Active",Assignments!$V$2:$V$769,"<="&C$4,Assignments!$W$2:$W$769,">="&C$4)+SUMIFS(Assignments!$AA$2:$AA$769,Assignments!$A$2:$A$769,$A5,Assignments!$G$2:$G$769,"Active",Assignments!$Y$2:$Y$769,"<="&C$4,Assignments!$Z$2:$Z$769,">="&C$4)) | D5: =IF($A5="","",SUMIFS(Assignments!$X$2:$X$769,Assignments!$A$2:$A$769,$A5,Assignments!$G$2:$G$769,"Active",Assignments!$V$2:$V$769,"<="&D$4,Assignments!$W$2:$W$769,">="&D$4)+SUMIFS(Assignments!$AA$2:$AA$769,Assignments!$A$2:$A$769,$A5,Assignments!$G$2:$G$769,"Active",Assignments!$Y$2:$Y$769,"<="&D$4,Assignments!$Z$2:$Z$769,">="&D$4)) | E5: =IF($A5="","",SUMIFS(Assignments!$X$2:$X$769,Assignments!$A$2:$A$769,$A5,Assignments!$G$2:$G$769,"Active",Assignments!$V$2:$V$769,"<="&E$4,Assignments!$W$2:$W$769,">="&E$4)+SUMIFS(Assignments!$AA$2:$AA$769,Assignments!$A$2:$A$769,$A5,Assignments!$G$2:$G$769,"Active",Assignments!$Y$2:$Y$769,"<="&E$4,Assignments!$Z$2:$Z$769,">="&E$4)) | F5: =IF($A5="","",SUMIFS(Assignments!$X$2:$X$769,Assignments!$A$2:$A$769,$A5,Assignments!$G$2:$G$769,"Active",Assignments!$V$2:$V$769,"<="&F$4,Assignments!$W$2:$W$769,">="&F$4)+SUMIFS(Assignments!$AA$2:$AA$769,Assignments!$A$2:$A$769,$A5,Assignments!$G$2:$G$769,"Active",Assignments!$Y$2:$Y$769,"<="&F$4,Assignments!$Z$2:$Z$769,">="&F$4)) | G5: =IF($A5="","",SUMIFS(Assignments!$X$2:$X$769,Assignments!$A$2:$A$769,$A5,Assignments!$G$2:$G$769,"Active",Assignments!$V$2:$V$769,"<="&G$4,Assignments!$W$2:$W$769,">="&G$4)+SUMIFS(Assignments!$AA$2:$AA$769,Assignments!$A$2:$A$769,$A5,Assignments!$G$2:$G$769,"Active",Assignments!$Y$2:$Y$769,"<="&G$4,Assignments!$Z$2:$Z$769,">="&G$4)) | H5: =IF($A5="","",SUMIFS(Assignments!$X$2:$X$769,Assignments!$A$2:$A$769,$A5,Assignments!$G$2:$G$769,"Active",Assignments!$V$2:$V$769,"<="&H$4,Assignments!$W$2:$W$769,">="&H$4)+SUMIFS(Assignments!$AA$2:$AA$769,Assignments!$A$2:$A$769,$A5,Assignments!$G$2:$G$769,"Active",Assignments!$Y$2:$Y$769,"<="&H$4,Assignments!$Z$2:$Z$769,">="&H$4)) | I5: =IF($A5="","",SUMIFS(Assignments!$X$2:$X$769,Assignments!$A$2:$A$769,$A5,Assignments!$G$2:$G$769,"Active",Assignments!$V$2:$V$769,"<="&I$4,Assignments!$W$2:$W$769,">="&I$4)+SUMIFS(Assignments!$AA$2:$AA$769,Assignments!$A$2:$A$769,$A5,Assignments!$G$2:$G$769,"Active",Assignments!$Y$2:$Y$769,"<="&I$4,Assignments!$Z$2:$Z$769,">="&I$4)) | J5: =IF($A5="","",SUMIFS(Assignments!$X$2:$X$769,Assignments!$A$2:$A$769,$A5,Assignments!$G$2:$G$769,"Active",Assignments!$V$2:$V$769,"<="&J$4,Assignments!$W$2:$W$769,">="&J$4)+SUMIFS(Assignments!$AA$2:$AA$769,Assignments!$A$2:$A$769,$A5,Assignments!$G$2:$G$769,"Active",Assignments!$Y$2:$Y$769,"<="&J$4,Assignments!$Z$2:$Z$769,">="&J$4)) | ... AB5: =IF($A5="","",SUMIFS(Assignments!$X$2:$X$769,Assignments!$A$2:$A$769,$A5,Assignments!$G$2:$G$769,"Active",Assignments!$V$2:$V$769,"<="&AB$4,Assignments!$W$2:$W$769,">="&AB$4)+SUMIFS(Assignments!$AA$2:$AA$769,Assignments!$A$2:$A$769,$A5,Assignments!$G$2:$G$769,"Active",Assignments!$Y$2:$Y$769,"<="&AB$4,Assignments!$Z$2:$Z$769,">="&AB$4))
A6: =IF(Roster!$A3="","",Roster!$A3) | B6: =IF($A6="","",IFERROR(INDEX(Roster!$D$2:$D$40,MATCH($A6,Roster!$A$2:$A$40,0)),"")) | C6: =IF($A6="","",SUMIFS(Assignments!$X$2:$X$769,Assignments!$A$2:$A$769,$A6,Assignments!$G$2:$G$769,"Active",Assignments!$V$2:$V$769,"<="&C$4,Assignments!$W$2:$W$769,">="&C$4)+SUMIFS(Assignments!$AA$2:$AA$769,Assignments!$A$2:$A$769,$A6,Assignments!$G$2:$G$769,"Active",Assignments!$Y$2:$Y$769,"<="&C$4,Assignments!$Z$2:$Z$769,">="&C$4)) | D6: =IF($A6="","",SUMIFS(Assignments!$X$2:$X$769,Assignments!$A$2:$A$769,$A6,Assignments!$G$2:$G$769,"Active",Assignments!$V$2:$V$769,"<="&D$4,Assignments!$W$2:$W$769,">="&D$4)+SUMIFS(Assignments!$AA$2:$AA$769,Assignments!$A$2:$A$769,$A6,Assignments!$G$2:$G$769,"Active",Assignments!$Y$2:$Y$769,"<="&D$4,Assignments!$Z$2:$Z$769,">="&D$4)) | E6: =IF($A6="","",SUMIFS(Assignments!$X$2:$X$769,Assignments!$A$2:$A$769,$A6,Assignments!$G$2:$G$769,"Active",Assignments!$V$2:$V$769,"<="&E$4,Assignments!$W$2:$W$769,">="&E$4)+SUMIFS(Assignments!$AA$2:$AA$769,Assignments!$A$2:$A$769,$A6,Assignments!$G$2:$G$769,"Active",Assignments!$Y$2:$Y$769,"<="&E$4,Assignments!$Z$2:$Z$769,">="&E$4)) | F6: =IF($A6="","",SUMIFS(Assignments!$X$2:$X$769,Assignments!$A$2:$A$769,$A6,Assignments!$G$2:$G$769,"Active",Assignments!$V$2:$V$769,"<="&F$4,Assignments!$W$2:$W$769,">="&F$4)+SUMIFS(Assignments!$AA$2:$AA$769,Assignments!$A$2:$A$769,$A6,Assignments!$G$2:$G$769,"Active",Assignments!$Y$2:$Y$769,"<="&F$4,Assignments!$Z$2:$Z$769,">="&F$4)) | G6: =IF($A6="","",SUMIFS(Assignments!$X$2:$X$769,Assignments!$A$2:$A$769,$A6,Assignments!$G$2:$G$769,"Active",Assignments!$V$2:$V$769,"<="&G$4,Assignments!$W$2:$W$769,">="&G$4)+SUMIFS(Assignments!$AA$2:$AA$769,Assignments!$A$2:$A$769,$A6,Assignments!$G$2:$G$769,"Active",Assignments!$Y$2:$Y$769,"<="&G$4,Assignments!$Z$2:$Z$769,">="&G$4)) | H6: =IF($A6="","",SUMIFS(Assignments!$X$2:$X$769,Assignments!$A$2:$A$769,$A6,Assignments!$G$2:$G$769,"Active",Assignments!$V$2:$V$769,"<="&H$4,Assignments!$W$2:$W$769,">="&H$4)+SUMIFS(Assignments!$AA$2:$AA$769,Assignments!$A$2:$A$769,$A6,Assignments!$G$2:$G$769,"Active",Assignments!$Y$2:$Y$769,"<="&H$4,Assignments!$Z$2:$Z$769,">="&H$4)) | I6: =IF($A6="","",SUMIFS(Assignments!$X$2:$X$769,Assignments!$A$2:$A$769,$A6,Assignments!$G$2:$G$769,"Active",Assignments!$V$2:$V$769,"<="&I$4,Assignments!$W$2:$W$769,">="&I$4)+SUMIFS(Assignments!$AA$2:$AA$769,Assignments!$A$2:$A$769,$A6,Assignments!$G$2:$G$769,"Active",Assignments!$Y$2:$Y$769,"<="&I$4,Assignments!$Z$2:$Z$769,">="&I$4)) | J6: =IF($A6="","",SUMIFS(Assignments!$X$2:$X$769,Assignments!$A$2:$A$769,$A6,Assignments!$G$2:$G$769,"Active",Assignments!$V$2:$V$769,"<="&J$4,Assignments!$W$2:$W$769,">="&J$4)+SUMIFS(Assignments!$AA$2:$AA$769,Assignments!$A$2:$A$769,$A6,Assignments!$G$2:$G$769,"Active",Assignments!$Y$2:$Y$769,"<="&J$4,Assignments!$Z$2:$Z$769,">="&J$4)) | ... AB6: =IF($A6="","",SUMIFS(Assignments!$X$2:$X$769,Assignments!$A$2:$A$769,$A6,Assignments!$G$2:$G$769,"Active",Assignments!$V$2:$V$769,"<="&AB$4,Assignments!$W$2:$W$769,">="&AB$4)+SUMIFS(Assignments!$AA$2:$AA$769,Assignments!$A$2:$A$769,$A6,Assignments!$G$2:$G$769,"Active",Assignments!$Y$2:$Y$769,"<="&AB$4,Assignments!$Z$2:$Z$769,">="&AB$4))
A7: =IF(Roster!$A4="","",Roster!$A4) | B7: =IF($A7="","",IFERROR(INDEX(Roster!$D$2:$D$40,MATCH($A7,Roster!$A$2:$A$40,0)),"")) | C7: =IF($A7="","",SUMIFS(Assignments!$X$2:$X$769,Assignments!$A$2:$A$769,$A7,Assignments!$G$2:$G$769,"Active",Assignments!$V$2:$V$769,"<="&C$4,Assignments!$W$2:$W$769,">="&C$4)+SUMIFS(Assignments!$AA$2:$AA$769,Assignments!$A$2:$A$769,$A7,Assignments!$G$2:$G$769,"Active",Assignments!$Y$2:$Y$769,"<="&C$4,Assignments!$Z$2:$Z$769,">="&C$4)) | D7: =IF($A7="","",SUMIFS(Assignments!$X$2:$X$769,Assignments!$A$2:$A$769,$A7,Assignments!$G$2:$G$769,"Active",Assignments!$V$2:$V$769,"<="&D$4,Assignments!$W$2:$W$769,">="&D$4)+SUMIFS(Assignments!$AA$2:$AA$769,Assignments!$A$2:$A$769,$A7,Assignments!$G$2:$G$769,"Active",Assignments!$Y$2:$Y$769,"<="&D$4,Assignments!$Z$2:$Z$769,">="&D$4)) | E7: =IF($A7="","",SUMIFS(Assignments!$X$2:$X$769,Assignments!$A$2:$A$769,$A7,Assignments!$G$2:$G$769,"Active",Assignments!$V$2:$V$769,"<="&E$4,Assignments!$W$2:$W$769,">="&E$4)+SUMIFS(Assignments!$AA$2:$AA$769,Assignments!$A$2:$A$769,$A7,Assignments!$G$2:$G$769,"Active",Assignments!$Y$2:$Y$769,"<="&E$4,Assignments!$Z$2:$Z$769,">="&E$4)) | F7: =IF($A7="","",SUMIFS(Assignments!$X$2:$X$769,Assignments!$A$2:$A$769,$A7,Assignments!$G$2:$G$769,"Active",Assignments!$V$2:$V$769,"<="&F$4,Assignments!$W$2:$W$769,">="&F$4)+SUMIFS(Assignments!$AA$2:$AA$769,Assignments!$A$2:$A$769,$A7,Assignments!$G$2:$G$769,"Active",Assignments!$Y$2:$Y$769,"<="&F$4,Assignments!$Z$2:$Z$769,">="&F$4)) | G7: =IF($A7="","",SUMIFS(Assignments!$X$2:$X$769,Assignments!$A$2:$A$769,$A7,Assignments!$G$2:$G$769,"Active",Assignments!$V$2:$V$769,"<="&G$4,Assignments!$W$2:$W$769,">="&G$4)+SUMIFS(Assignments!$AA$2:$AA$769,Assignments!$A$2:$A$769,$A7,Assignments!$G$2:$G$769,"Active",Assignments!$Y$2:$Y$769,"<="&G$4,Assignments!$Z$2:$Z$769,">="&G$4)) | H7: =IF($A7="","",SUMIFS(Assignments!$X$2:$X$769,Assignments!$A$2:$A$769,$A7,Assignments!$G$2:$G$769,"Active",Assignments!$V$2:$V$769,"<="&H$4,Assignments!$W$2:$W$769,">="&H$4)+SUMIFS(Assignments!$AA$2:$AA$769,Assignments!$A$2:$A$769,$A7,Assignments!$G$2:$G$769,"Active",Assignments!$Y$2:$Y$769,"<="&H$4,Assignments!$Z$2:$Z$769,">="&H$4)) | I7: =IF($A7="","",SUMIFS(Assignments!$X$2:$X$769,Assignments!$A$2:$A$769,$A7,Assignments!$G$2:$G$769,"Active",Assignments!$V$2:$V$769,"<="&I$4,Assignments!$W$2:$W$769,">="&I$4)+SUMIFS(Assignments!$AA$2:$AA$769,Assignments!$A$2:$A$769,$A7,Assignments!$G$2:$G$769,"Active",Assignments!$Y$2:$Y$769,"<="&I$4,Assignments!$Z$2:$Z$769,">="&I$4)) | J7: =IF($A7="","",SUMIFS(Assignments!$X$2:$X$769,Assignments!$A$2:$A$769,$A7,Assignments!$G$2:$G$769,"Active",Assignments!$V$2:$V$769,"<="&J$4,Assignments!$W$2:$W$769,">="&J$4)+SUMIFS(Assignments!$AA$2:$AA$769,Assignments!$A$2:$A$769,$A7,Assignments!$G$2:$G$769,"Active",Assignments!$Y$2:$Y$769,"<="&J$4,Assignments!$Z$2:$Z$769,">="&J$4)) | ... AB7: =IF($A7="","",SUMIFS(Assignments!$X$2:$X$769,Assignments!$A$2:$A$769,$A7,Assignments!$G$2:$G$769,"Active",Assignments!$V$2:$V$769,"<="&AB$4,Assignments!$W$2:$W$769,">="&AB$4)+SUMIFS(Assignments!$AA$2:$AA$769,Assignments!$A$2:$A$769,$A7,Assignments!$G$2:$G$769,"Active",Assignments!$Y$2:$Y$769,"<="&AB$4,Assignments!$Z$2:$Z$769,">="&AB$4))
A8: =IF(Roster!$A5="","",Roster!$A5) | B8: =IF($A8="","",IFERROR(INDEX(Roster!$D$2:$D$40,MATCH($A8,Roster!$A$2:$A$40,0)),"")) | C8: =IF($A8="","",SUMIFS(Assignments!$X$2:$X$769,Assignments!$A$2:$A$769,$A8,Assignments!$G$2:$G$769,"Active",Assignments!$V$2:$V$769,"<="&C$4,Assignments!$W$2:$W$769,">="&C$4)+SUMIFS(Assignments!$AA$2:$AA$769,Assignments!$A$2:$A$769,$A8,Assignments!$G$2:$G$769,"Active",Assignments!$Y$2:$Y$769,"<="&C$4,Assignments!$Z$2:$Z$769,">="&C$4)) | D8: =IF($A8="","",SUMIFS(Assignments!$X$2:$X$769,Assignments!$A$2:$A$769,$A8,Assignments!$G$2:$G$769,"Active",Assignments!$V$2:$V$769,"<="&D$4,Assignments!$W$2:$W$769,">="&D$4)+SUMIFS(Assignments!$AA$2:$AA$769,Assignments!$A$2:$A$769,$A8,Assignments!$G$2:$G$769,"Active",Assignments!$Y$2:$Y$769,"<="&D$4,Assignments!$Z$2:$Z$769,">="&D$4)) | E8: =IF($A8="","",SUMIFS(Assignments!$X$2:$X$769,Assignments!$A$2:$A$769,$A8,Assignments!$G$2:$G$769,"Active",Assignments!$V$2:$V$769,"<="&E$4,Assignments!$W$2:$W$769,">="&E$4)+SUMIFS(Assignments!$AA$2:$AA$769,Assignments!$A$2:$A$769,$A8,Assignments!$G$2:$G$769,"Active",Assignments!$Y$2:$Y$769,"<="&E$4,Assignments!$Z$2:$Z$769,">="&E$4)) | F8: =IF($A8="","",SUMIFS(Assignments!$X$2:$X$769,Assignments!$A$2:$A$769,$A8,Assignments!$G$2:$G$769,"Active",Assignments!$V$2:$V$769,"<="&F$4,Assignments!$W$2:$W$769,">="&F$4)+SUMIFS(Assignments!$AA$2:$AA$769,Assignments!$A$2:$A$769,$A8,Assignments!$G$2:$G$769,"Active",Assignments!$Y$2:$Y$769,"<="&F$4,Assignments!$Z$2:$Z$769,">="&F$4)) | G8: =IF($A8="","",SUMIFS(Assignments!$X$2:$X$769,Assignments!$A$2:$A$769,$A8,Assignments!$G$2:$G$769,"Active",Assignments!$V$2:$V$769,"<="&G$4,Assignments!$W$2:$W$769,">="&G$4)+SUMIFS(Assignments!$AA$2:$AA$769,Assignments!$A$2:$A$769,$A8,Assignments!$G$2:$G$769,"Active",Assignments!$Y$2:$Y$769,"<="&G$4,Assignments!$Z$2:$Z$769,">="&G$4)) | H8: =IF($A8="","",SUMIFS(Assignments!$X$2:$X$769,Assignments!$A$2:$A$769,$A8,Assignments!$G$2:$G$769,"Active",Assignments!$V$2:$V$769,"<="&H$4,Assignments!$W$2:$W$769,">="&H$4)+SUMIFS(Assignments!$AA$2:$AA$769,Assignments!$A$2:$A$769,$A8,Assignments!$G$2:$G$769,"Active",Assignments!$Y$2:$Y$769,"<="&H$4,Assignments!$Z$2:$Z$769,">="&H$4)) | I8: =IF($A8="","",SUMIFS(Assignments!$X$2:$X$769,Assignments!$A$2:$A$769,$A8,Assignments!$G$2:$G$769,"Active",Assignments!$V$2:$V$769,"<="&I$4,Assignments!$W$2:$W$769,">="&I$4)+SUMIFS(Assignments!$AA$2:$AA$769,Assignments!$A$2:$A$769,$A8,Assignments!$G$2:$G$769,"Active",Assignments!$Y$2:$Y$769,"<="&I$4,Assignments!$Z$2:$Z$769,">="&I$4)) | J8: =IF($A8="","",SUMIFS(Assignments!$X$2:$X$769,Assignments!$A$2:$A$769,$A8,Assignments!$G$2:$G$769,"Active",Assignments!$V$2:$V$769,"<="&J$4,Assignments!$W$2:$W$769,">="&J$4)+SUMIFS(Assignments!$AA$2:$AA$769,Assignments!$A$2:$A$769,$A8,Assignments!$G$2:$G$769,"Active",Assignments!$Y$2:$Y$769,"<="&J$4,Assignments!$Z$2:$Z$769,">="&J$4)) | ... AB8: =IF($A8="","",SUMIFS(Assignments!$X$2:$X$769,Assignments!$A$2:$A$769,$A8,Assignments!$G$2:$G$769,"Active",Assignments!$V$2:$V$769,"<="&AB$4,Assignments!$W$2:$W$769,">="&AB$4)+SUMIFS(Assignments!$AA$2:$AA$769,Assignments!$A$2:$A$769,$A8,Assignments!$G$2:$G$769,"Active",Assignments!$Y$2:$Y$769,"<="&AB$4,Assignments!$Z$2:$Z$769,">="&AB$4))
A9: =IF(Roster!$A6="","",Roster!$A6) | B9: =IF($A9="","",IFERROR(INDEX(Roster!$D$2:$D$40,MATCH($A9,Roster!$A$2:$A$40,0)),"")) | C9: =IF($A9="","",SUMIFS(Assignments!$X$2:$X$769,Assignments!$A$2:$A$769,$A9,Assignments!$G$2:$G$769,"Active",Assignments!$V$2:$V$769,"<="&C$4,Assignments!$W$2:$W$769,">="&C$4)+SUMIFS(Assignments!$AA$2:$AA$769,Assignments!$A$2:$A$769,$A9,Assignments!$G$2:$G$769,"Active",Assignments!$Y$2:$Y$769,"<="&C$4,Assignments!$Z$2:$Z$769,">="&C$4)) | D9: =IF($A9="","",SUMIFS(Assignments!$X$2:$X$769,Assignments!$A$2:$A$769,$A9,Assignments!$G$2:$G$769,"Active",Assignments!$V$2:$V$769,"<="&D$4,Assignments!$W$2:$W$769,">="&D$4)+SUMIFS(Assignments!$AA$2:$AA$769,Assignments!$A$2:$A$769,$A9,Assignments!$G$2:$G$769,"Active",Assignments!$Y$2:$Y$769,"<="&D$4,Assignments!$Z$2:$Z$769,">="&D$4)) | E9: =IF($A9="","",SUMIFS(Assignments!$X$2:$X$769,Assignments!$A$2:$A$769,$A9,Assignments!$G$2:$G$769,"Active",Assignments!$V$2:$V$769,"<="&E$4,Assignments!$W$2:$W$769,">="&E$4)+SUMIFS(Assignments!$AA$2:$AA$769,Assignments!$A$2:$A$769,$A9,Assignments!$G$2:$G$769,"Active",Assignments!$Y$2:$Y$769,"<="&E$4,Assignments!$Z$2:$Z$769,">="&E$4)) | F9: =IF($A9="","",SUMIFS(Assignments!$X$2:$X$769,Assignments!$A$2:$A$769,$A9,Assignments!$G$2:$G$769,"Active",Assignments!$V$2:$V$769,"<="&F$4,Assignments!$W$2:$W$769,">="&F$4)+SUMIFS(Assignments!$AA$2:$AA$769,Assignments!$A$2:$A$769,$A9,Assignments!$G$2:$G$769,"Active",Assignments!$Y$2:$Y$769,"<="&F$4,Assignments!$Z$2:$Z$769,">="&F$4)) | G9: =IF($A9="","",SUMIFS(Assignments!$X$2:$X$769,Assignments!$A$2:$A$769,$A9,Assignments!$G$2:$G$769,"Active",Assignments!$V$2:$V$769,"<="&G$4,Assignments!$W$2:$W$769,">="&G$4)+SUMIFS(Assignments!$AA$2:$AA$769,Assignments!$A$2:$A$769,$A9,Assignments!$G$2:$G$769,"Active",Assignments!$Y$2:$Y$769,"<="&G$4,Assignments!$Z$2:$Z$769,">="&G$4)) | H9: =IF($A9="","",SUMIFS(Assignments!$X$2:$X$769,Assignments!$A$2:$A$769,$A9,Assignments!$G$2:$G$769,"Active",Assignments!$V$2:$V$769,"<="&H$4,Assignments!$W$2:$W$769,">="&H$4)+SUMIFS(Assignments!$AA$2:$AA$769,Assignments!$A$2:$A$769,$A9,Assignments!$G$2:$G$769,"Active",Assignments!$Y$2:$Y$769,"<="&H$4,Assignments!$Z$2:$Z$769,">="&H$4)) | I9: =IF($A9="","",SUMIFS(Assignments!$X$2:$X$769,Assignments!$A$2:$A$769,$A9,Assignments!$G$2:$G$769,"Active",Assignments!$V$2:$V$769,"<="&I$4,Assignments!$W$2:$W$769,">="&I$4)+SUMIFS(Assignments!$AA$2:$AA$769,Assignments!$A$2:$A$769,$A9,Assignments!$G$2:$G$769,"Active",Assignments!$Y$2:$Y$769,"<="&I$4,Assignments!$Z$2:$Z$769,">="&I$4)) | J9: =IF($A9="","",SUMIFS(Assignments!$X$2:$X$769,Assignments!$A$2:$A$769,$A9,Assignments!$G$2:$G$769,"Active",Assignments!$V$2:$V$769,"<="&J$4,Assignments!$W$2:$W$769,">="&J$4)+SUMIFS(Assignments!$AA$2:$AA$769,Assignments!$A$2:$A$769,$A9,Assignments!$G$2:$G$769,"Active",Assignments!$Y$2:$Y$769,"<="&J$4,Assignments!$Z$2:$Z$769,">="&J$4)) | ... AB9: =IF($A9="","",SUMIFS(Assignments!$X$2:$X$769,Assignments!$A$2:$A$769,$A9,Assignments!$G$2:$G$769,"Active",Assignments!$V$2:$V$769,"<="&AB$4,Assignments!$W$2:$W$769,">="&AB$4)+SUMIFS(Assignments!$AA$2:$AA$769,Assignments!$A$2:$A$769,$A9,Assignments!$G$2:$G$769,"Active",Assignments!$Y$2:$Y$769,"<="&AB$4,Assignments!$Z$2:$Z$769,">="&AB$4))
A10: =IF(Roster!$A7="","",Roster!$A7) | B10: =IF($A10="","",IFERROR(INDEX(Roster!$D$2:$D$40,MATCH($A10,Roster!$A$2:$A$40,0)),"")) | C10: =IF($A10="","",SUMIFS(Assignments!$X$2:$X$769,Assignments!$A$2:$A$769,$A10,Assignments!$G$2:$G$769,"Active",Assignments!$V$2:$V$769,"<="&C$4,Assignments!$W$2:$W$769,">="&C$4)+SUMIFS(Assignments!$AA$2:$AA$769,Assignments!$A$2:$A$769,$A10,Assignments!$G$2:$G$769,"Active",Assignments!$Y$2:$Y$769,"<="&C$4,Assignments!$Z$2:$Z$769,">="&C$4)) | D10: =IF($A10="","",SUMIFS(Assignments!$X$2:$X$769,Assignments!$A$2:$A$769,$A10,Assignments!$G$2:$G$769,"Active",Assignments!$V$2:$V$769,"<="&D$4,Assignments!$W$2:$W$769,">="&D$4)+SUMIFS(Assignments!$AA$2:$AA$769,Assignments!$A$2:$A$769,$A10,Assignments!$G$2:$G$769,"Active",Assignments!$Y$2:$Y$769,"<="&D$4,Assignments!$Z$2:$Z$769,">="&D$4)) | E10: =IF($A10="","",SUMIFS(Assignments!$X$2:$X$769,Assignments!$A$2:$A$769,$A10,Assignments!$G$2:$G$769,"Active",Assignments!$V$2:$V$769,"<="&E$4,Assignments!$W$2:$W$769,">="&E$4)+SUMIFS(Assignments!$AA$2:$AA$769,Assignments!$A$2:$A$769,$A10,Assignments!$G$2:$G$769,"Active",Assignments!$Y$2:$Y$769,"<="&E$4,Assignments!$Z$2:$Z$769,">="&E$4)) | F10: =IF($A10="","",SUMIFS(Assignments!$X$2:$X$769,Assignments!$A$2:$A$769,$A10,Assignments!$G$2:$G$769,"Active",Assignments!$V$2:$V$769,"<="&F$4,Assignments!$W$2:$W$769,">="&F$4)+SUMIFS(Assignments!$AA$2:$AA$769,Assignments!$A$2:$A$769,$A10,Assignments!$G$2:$G$769,"Active",Assignments!$Y$2:$Y$769,"<="&F$4,Assignments!$Z$2:$Z$769,">="&F$4)) | G10: =IF($A10="","",SUMIFS(Assignments!$X$2:$X$769,Assignments!$A$2:$A$769,$A10,Assignments!$G$2:$G$769,"Active",Assignments!$V$2:$V$769,"<="&G$4,Assignments!$W$2:$W$769,">="&G$4)+SUMIFS(Assignments!$AA$2:$AA$769,Assignments!$A$2:$A$769,$A10,Assignments!$G$2:$G$769,"Active",Assignments!$Y$2:$Y$769,"<="&G$4,Assignments!$Z$2:$Z$769,">="&G$4)) | H10: =IF($A10="","",SUMIFS(Assignments!$X$2:$X$769,Assignments!$A$2:$A$769,$A10,Assignments!$G$2:$G$769,"Active",Assignments!$V$2:$V$769,"<="&H$4,Assignments!$W$2:$W$769,">="&H$4)+SUMIFS(Assignments!$AA$2:$AA$769,Assignments!$A$2:$A$769,$A10,Assignments!$G$2:$G$769,"Active",Assignments!$Y$2:$Y$769,"<="&H$4,Assignments!$Z$2:$Z$769,">="&H$4)) | I10: =IF($A10="","",SUMIFS(Assignments!$X$2:$X$769,Assignments!$A$2:$A$769,$A10,Assignments!$G$2:$G$769,"Active",Assignments!$V$2:$V$769,"<="&I$4,Assignments!$W$2:$W$769,">="&I$4)+SUMIFS(Assignments!$AA$2:$AA$769,Assignments!$A$2:$A$769,$A10,Assignments!$G$2:$G$769,"Active",Assignments!$Y$2:$Y$769,"<="&I$4,Assignments!$Z$2:$Z$769,">="&I$4)) | J10: =IF($A10="","",SUMIFS(Assignments!$X$2:$X$769,Assignments!$A$2:$A$769,$A10,Assignments!$G$2:$G$769,"Active",Assignments!$V$2:$V$769,"<="&J$4,Assignments!$W$2:$W$769,">="&J$4)+SUMIFS(Assignments!$AA$2:$AA$769,Assignments!$A$2:$A$769,$A10,Assignments!$G$2:$G$769,"Active",Assignments!$Y$2:$Y$769,"<="&J$4,Assignments!$Z$2:$Z$769,">="&J$4)) | ... AB10: =IF($A10="","",SUMIFS(Assignments!$X$2:$X$769,Assignments!$A$2:$A$769,$A10,Assignments!$G$2:$G$769,"Active",Assignments!$V$2:$V$769,"<="&AB$4,Assignments!$W$2:$W$769,">="&AB$4)+SUMIFS(Assignments!$AA$2:$AA$769,Assignments!$A$2:$A$769,$A10,Assignments!$G$2:$G$769,"Active",Assignments!$Y$2:$Y$769,"<="&AB$4,Assignments!$Z$2:$Z$769,">="&AB$4))
A11: =IF(Roster!$A8="","",Roster!$A8) | B11: =IF($A11="","",IFERROR(INDEX(Roster!$D$2:$D$40,MATCH($A11,Roster!$A$2:$A$40,0)),"")) | C11: =IF($A11="","",SUMIFS(Assignments!$X$2:$X$769,Assignments!$A$2:$A$769,$A11,Assignments!$G$2:$G$769,"Active",Assignments!$V$2:$V$769,"<="&C$4,Assignments!$W$2:$W$769,">="&C$4)+SUMIFS(Assignments!$AA$2:$AA$769,Assignments!$A$2:$A$769,$A11,Assignments!$G$2:$G$769,"Active",Assignments!$Y$2:$Y$769,"<="&C$4,Assignments!$Z$2:$Z$769,">="&C$4)) | D11: =IF($A11="","",SUMIFS(Assignments!$X$2:$X$769,Assignments!$A$2:$A$769,$A11,Assignments!$G$2:$G$769,"Active",Assignments!$V$2:$V$769,"<="&D$4,Assignments!$W$2:$W$769,">="&D$4)+SUMIFS(Assignments!$AA$2:$AA$769,Assignments!$A$2:$A$769,$A11,Assignments!$G$2:$G$769,"Active",Assignments!$Y$2:$Y$769,"<="&D$4,Assignments!$Z$2:$Z$769,">="&D$4)) | E11: =IF($A11="","",SUMIFS(Assignments!$X$2:$X$769,Assignments!$A$2:$A$769,$A11,Assignments!$G$2:$G$769,"Active",Assignments!$V$2:$V$769,"<="&E$4,Assignments!$W$2:$W$769,">="&E$4)+SUMIFS(Assignments!$AA$2:$AA$769,Assignments!$A$2:$A$769,$A11,Assignments!$G$2:$G$769,"Active",Assignments!$Y$2:$Y$769,"<="&E$4,Assignments!$Z$2:$Z$769,">="&E$4)) | F11: =IF($A11="","",SUMIFS(Assignments!$X$2:$X$769,Assignments!$A$2:$A$769,$A11,Assignments!$G$2:$G$769,"Active",Assignments!$V$2:$V$769,"<="&F$4,Assignments!$W$2:$W$769,">="&F$4)+SUMIFS(Assignments!$AA$2:$AA$769,Assignments!$A$2:$A$769,$A11,Assignments!$G$2:$G$769,"Active",Assignments!$Y$2:$Y$769,"<="&F$4,Assignments!$Z$2:$Z$769,">="&F$4)) | G11: =IF($A11="","",SUMIFS(Assignments!$X$2:$X$769,Assignments!$A$2:$A$769,$A11,Assignments!$G$2:$G$769,"Active",Assignments!$V$2:$V$769,"<="&G$4,Assignments!$W$2:$W$769,">="&G$4)+SUMIFS(Assignments!$AA$2:$AA$769,Assignments!$A$2:$A$769,$A11,Assignments!$G$2:$G$769,"Active",Assignments!$Y$2:$Y$769,"<="&G$4,Assignments!$Z$2:$Z$769,">="&G$4)) | H11: =IF($A11="","",SUMIFS(Assignments!$X$2:$X$769,Assignments!$A$2:$A$769,$A11,Assignments!$G$2:$G$769,"Active",Assignments!$V$2:$V$769,"<="&H$4,Assignments!$W$2:$W$769,">="&H$4)+SUMIFS(Assignments!$AA$2:$AA$769,Assignments!$A$2:$A$769,$A11,Assignments!$G$2:$G$769,"Active",Assignments!$Y$2:$Y$769,"<="&H$4,Assignments!$Z$2:$Z$769,">="&H$4)) | I11: =IF($A11="","",SUMIFS(Assignments!$X$2:$X$769,Assignments!$A$2:$A$769,$A11,Assignments!$G$2:$G$769,"Active",Assignments!$V$2:$V$769,"<="&I$4,Assignments!$W$2:$W$769,">="&I$4)+SUMIFS(Assignments!$AA$2:$AA$769,Assignments!$A$2:$A$769,$A11,Assignments!$G$2:$G$769,"Active",Assignments!$Y$2:$Y$769,"<="&I$4,Assignments!$Z$2:$Z$769,">="&I$4)) | J11: =IF($A11="","",SUMIFS(Assignments!$X$2:$X$769,Assignments!$A$2:$A$769,$A11,Assignments!$G$2:$G$769,"Active",Assignments!$V$2:$V$769,"<="&J$4,Assignments!$W$2:$W$769,">="&J$4)+SUMIFS(Assignments!$AA$2:$AA$769,Assignments!$A$2:$A$769,$A11,Assignments!$G$2:$G$769,"Active",Assignments!$Y$2:$Y$769,"<="&J$4,Assignments!$Z$2:$Z$769,">="&J$4)) | ... AB11: =IF($A11="","",SUMIFS(Assignments!$X$2:$X$769,Assignments!$A$2:$A$769,$A11,Assignments!$G$2:$G$769,"Active",Assignments!$V$2:$V$769,"<="&AB$4,Assignments!$W$2:$W$769,">="&AB$4)+SUMIFS(Assignments!$AA$2:$AA$769,Assignments!$A$2:$A$769,$A11,Assignments!$G$2:$G$769,"Active",Assignments!$Y$2:$Y$769,"<="&AB$4,Assignments!$Z$2:$Z$769,">="&AB$4))
A12: =IF(Roster!$A9="","",Roster!$A9) | B12: =IF($A12="","",IFERROR(INDEX(Roster!$D$2:$D$40,MATCH($A12,Roster!$A$2:$A$40,0)),"")) | C12: =IF($A12="","",SUMIFS(Assignments!$X$2:$X$769,Assignments!$A$2:$A$769,$A12,Assignments!$G$2:$G$769,"Active",Assignments!$V$2:$V$769,"<="&C$4,Assignments!$W$2:$W$769,">="&C$4)+SUMIFS(Assignments!$AA$2:$AA$769,Assignments!$A$2:$A$769,$A12,Assignments!$G$2:$G$769,"Active",Assignments!$Y$2:$Y$769,"<="&C$4,Assignments!$Z$2:$Z$769,">="&C$4)) | D12: =IF($A12="","",SUMIFS(Assignments!$X$2:$X$769,Assignments!$A$2:$A$769,$A12,Assignments!$G$2:$G$769,"Active",Assignments!$V$2:$V$769,"<="&D$4,Assignments!$W$2:$W$769,">="&D$4)+SUMIFS(Assignments!$AA$2:$AA$769,Assignments!$A$2:$A$769,$A12,Assignments!$G$2:$G$769,"Active",Assignments!$Y$2:$Y$769,"<="&D$4,Assignments!$Z$2:$Z$769,">="&D$4)) | E12: =IF($A12="","",SUMIFS(Assignments!$X$2:$X$769,Assignments!$A$2:$A$769,$A12,Assignments!$G$2:$G$769,"Active",Assignments!$V$2:$V$769,"<="&E$4,Assignments!$W$2:$W$769,">="&E$4)+SUMIFS(Assignments!$AA$2:$AA$769,Assignments!$A$2:$A$769,$A12,Assignments!$G$2:$G$769,"Active",Assignments!$Y$2:$Y$769,"<="&E$4,Assignments!$Z$2:$Z$769,">="&E$4)) | F12: =IF($A12="","",SUMIFS(Assignments!$X$2:$X$769,Assignments!$A$2:$A$769,$A12,Assignments!$G$2:$G$769,"Active",Assignments!$V$2:$V$769,"<="&F$4,Assignments!$W$2:$W$769,">="&F$4)+SUMIFS(Assignments!$AA$2:$AA$769,Assignments!$A$2:$A$769,$A12,Assignments!$G$2:$G$769,"Active",Assignments!$Y$2:$Y$769,"<="&F$4,Assignments!$Z$2:$Z$769,">="&F$4)) | G12: =IF($A12="","",SUMIFS(Assignments!$X$2:$X$769,Assignments!$A$2:$A$769,$A12,Assignments!$G$2:$G$769,"Active",Assignments!$V$2:$V$769,"<="&G$4,Assignments!$W$2:$W$769,">="&G$4)+SUMIFS(Assignments!$AA$2:$AA$769,Assignments!$A$2:$A$769,$A12,Assignments!$G$2:$G$769,"Active",Assignments!$Y$2:$Y$769,"<="&G$4,Assignments!$Z$2:$Z$769,">="&G$4)) | H12: =IF($A12="","",SUMIFS(Assignments!$X$2:$X$769,Assignments!$A$2:$A$769,$A12,Assignments!$G$2:$G$769,"Active",Assignments!$V$2:$V$769,"<="&H$4,Assignments!$W$2:$W$769,">="&H$4)+SUMIFS(Assignments!$AA$2:$AA$769,Assignments!$A$2:$A$769,$A12,Assignments!$G$2:$G$769,"Active",Assignments!$Y$2:$Y$769,"<="&H$4,Assignments!$Z$2:$Z$769,">="&H$4)) | I12: =IF($A12="","",SUMIFS(Assignments!$X$2:$X$769,Assignments!$A$2:$A$769,$A12,Assignments!$G$2:$G$769,"Active",Assignments!$V$2:$V$769,"<="&I$4,Assignments!$W$2:$W$769,">="&I$4)+SUMIFS(Assignments!$AA$2:$AA$769,Assignments!$A$2:$A$769,$A12,Assignments!$G$2:$G$769,"Active",Assignments!$Y$2:$Y$769,"<="&I$4,Assignments!$Z$2:$Z$769,">="&I$4)) | J12: =IF($A12="","",SUMIFS(Assignments!$X$2:$X$769,Assignments!$A$2:$A$769,$A12,Assignments!$G$2:$G$769,"Active",Assignments!$V$2:$V$769,"<="&J$4,Assignments!$W$2:$W$769,">="&J$4)+SUMIFS(Assignments!$AA$2:$AA$769,Assignments!$A$2:$A$769,$A12,Assignments!$G$2:$G$769,"Active",Assignments!$Y$2:$Y$769,"<="&J$4,Assignments!$Z$2:$Z$769,">="&J$4)) | ... AB12: =IF($A12="","",SUMIFS(Assignments!$X$2:$X$769,Assignments!$A$2:$A$769,$A12,Assignments!$G$2:$G$769,"Active",Assignments!$V$2:$V$769,"<="&AB$4,Assignments!$W$2:$W$769,">="&AB$4)+SUMIFS(Assignments!$AA$2:$AA$769,Assignments!$A$2:$A$769,$A12,Assignments!$G$2:$G$769,"Active",Assignments!$Y$2:$Y$769,"<="&AB$4,Assignments!$Z$2:$Z$769,">="&AB$4))
A13: =IF(Roster!$A10="","",Roster!$A10) | B13: =IF($A13="","",IFERROR(INDEX(Roster!$D$2:$D$40,MATCH($A13,Roster!$A$2:$A$40,0)),"")) | C13: =IF($A13="","",SUMIFS(Assignments!$X$2:$X$769,Assignments!$A$2:$A$769,$A13,Assignments!$G$2:$G$769,"Active",Assignments!$V$2:$V$769,"<="&C$4,Assignments!$W$2:$W$769,">="&C$4)+SUMIFS(Assignments!$AA$2:$AA$769,Assignments!$A$2:$A$769,$A13,Assignments!$G$2:$G$769,"Active",Assignments!$Y$2:$Y$769,"<="&C$4,Assignments!$Z$2:$Z$769,">="&C$4)) | D13: =IF($A13="","",SUMIFS(Assignments!$X$2:$X$769,Assignments!$A$2:$A$769,$A13,Assignments!$G$2:$G$769,"Active",Assignments!$V$2:$V$769,"<="&D$4,Assignments!$W$2:$W$769,">="&D$4)+SUMIFS(Assignments!$AA$2:$AA$769,Assignments!$A$2:$A$769,$A13,Assignments!$G$2:$G$769,"Active",Assignments!$Y$2:$Y$769,"<="&D$4,Assignments!$Z$2:$Z$769,">="&D$4)) | E13: =IF($A13="","",SUMIFS(Assignments!$X$2:$X$769,Assignments!$A$2:$A$769,$A13,Assignments!$G$2:$G$769,"Active",Assignments!$V$2:$V$769,"<="&E$4,Assignments!$W$2:$W$769,">="&E$4)+SUMIFS(Assignments!$AA$2:$AA$769,Assignments!$A$2:$A$769,$A13,Assignments!$G$2:$G$769,"Active",Assignments!$Y$2:$Y$769,"<="&E$4,Assignments!$Z$2:$Z$769,">="&E$4)) | F13: =IF($A13="","",SUMIFS(Assignments!$X$2:$X$769,Assignments!$A$2:$A$769,$A13,Assignments!$G$2:$G$769,"Active",Assignments!$V$2:$V$769,"<="&F$4,Assignments!$W$2:$W$769,">="&F$4)+SUMIFS(Assignments!$AA$2:$AA$769,Assignments!$A$2:$A$769,$A13,Assignments!$G$2:$G$769,"Active",Assignments!$Y$2:$Y$769,"<="&F$4,Assignments!$Z$2:$Z$769,">="&F$4)) | G13: =IF($A13="","",SUMIFS(Assignments!$X$2:$X$769,Assignments!$A$2:$A$769,$A13,Assignments!$G$2:$G$769,"Active",Assignments!$V$2:$V$769,"<="&G$4,Assignments!$W$2:$W$769,">="&G$4)+SUMIFS(Assignments!$AA$2:$AA$769,Assignments!$A$2:$A$769,$A13,Assignments!$G$2:$G$769,"Active",Assignments!$Y$2:$Y$769,"<="&G$4,Assignments!$Z$2:$Z$769,">="&G$4)) | H13: =IF($A13="","",SUMIFS(Assignments!$X$2:$X$769,Assignments!$A$2:$A$769,$A13,Assignments!$G$2:$G$769,"Active",Assignments!$V$2:$V$769,"<="&H$4,Assignments!$W$2:$W$769,">="&H$4)+SUMIFS(Assignments!$AA$2:$AA$769,Assignments!$A$2:$A$769,$A13,Assignments!$G$2:$G$769,"Active",Assignments!$Y$2:$Y$769,"<="&H$4,Assignments!$Z$2:$Z$769,">="&H$4)) | I13: =IF($A13="","",SUMIFS(Assignments!$X$2:$X$769,Assignments!$A$2:$A$769,$A13,Assignments!$G$2:$G$769,"Active",Assignments!$V$2:$V$769,"<="&I$4,Assignments!$W$2:$W$769,">="&I$4)+SUMIFS(Assignments!$AA$2:$AA$769,Assignments!$A$2:$A$769,$A13,Assignments!$G$2:$G$769,"Active",Assignments!$Y$2:$Y$769,"<="&I$4,Assignments!$Z$2:$Z$769,">="&I$4)) | J13: =IF($A13="","",SUMIFS(Assignments!$X$2:$X$769,Assignments!$A$2:$A$769,$A13,Assignments!$G$2:$G$769,"Active",Assignments!$V$2:$V$769,"<="&J$4,Assignments!$W$2:$W$769,">="&J$4)+SUMIFS(Assignments!$AA$2:$AA$769,Assignments!$A$2:$A$769,$A13,Assignments!$G$2:$G$769,"Active",Assignments!$Y$2:$Y$769,"<="&J$4,Assignments!$Z$2:$Z$769,">="&J$4)) | ... AB13: =IF($A13="","",SUMIFS(Assignments!$X$2:$X$769,Assignments!$A$2:$A$769,$A13,Assignments!$G$2:$G$769,"Active",Assignments!$V$2:$V$769,"<="&AB$4,Assignments!$W$2:$W$769,">="&AB$4)+SUMIFS(Assignments!$AA$2:$AA$769,Assignments!$A$2:$A$769,$A13,Assignments!$G$2:$G$769,"Active",Assignments!$Y$2:$Y$769,"<="&AB$4,Assignments!$Z$2:$Z$769,">="&AB$4))
A14: =IF(Roster!$A11="","",Roster!$A11) | B14: =IF($A14="","",IFERROR(INDEX(Roster!$D$2:$D$40,MATCH($A14,Roster!$A$2:$A$40,0)),"")) | C14: =IF($A14="","",SUMIFS(Assignments!$X$2:$X$769,Assignments!$A$2:$A$769,$A14,Assignments!$G$2:$G$769,"Active",Assignments!$V$2:$V$769,"<="&C$4,Assignments!$W$2:$W$769,">="&C$4)+SUMIFS(Assignments!$AA$2:$AA$769,Assignments!$A$2:$A$769,$A14,Assignments!$G$2:$G$769,"Active",Assignments!$Y$2:$Y$769,"<="&C$4,Assignments!$Z$2:$Z$769,">="&C$4)) | D14: =IF($A14="","",SUMIFS(Assignments!$X$2:$X$769,Assignments!$A$2:$A$769,$A14,Assignments!$G$2:$G$769,"Active",Assignments!$V$2:$V$769,"<="&D$4,Assignments!$W$2:$W$769,">="&D$4)+SUMIFS(Assignments!$AA$2:$AA$769,Assignments!$A$2:$A$769,$A14,Assignments!$G$2:$G$769,"Active",Assignments!$Y$2:$Y$769,"<="&D$4,Assignments!$Z$2:$Z$769,">="&D$4)) | E14: =IF($A14="","",SUMIFS(Assignments!$X$2:$X$769,Assignments!$A$2:$A$769,$A14,Assignments!$G$2:$G$769,"Active",Assignments!$V$2:$V$769,"<="&E$4,Assignments!$W$2:$W$769,">="&E$4)+SUMIFS(Assignments!$AA$2:$AA$769,Assignments!$A$2:$A$769,$A14,Assignments!$G$2:$G$769,"Active",Assignments!$Y$2:$Y$769,"<="&E$4,Assignments!$Z$2:$Z$769,">="&E$4)) | F14: =IF($A14="","",SUMIFS(Assignments!$X$2:$X$769,Assignments!$A$2:$A$769,$A14,Assignments!$G$2:$G$769,"Active",Assignments!$V$2:$V$769,"<="&F$4,Assignments!$W$2:$W$769,">="&F$4)+SUMIFS(Assignments!$AA$2:$AA$769,Assignments!$A$2:$A$769,$A14,Assignments!$G$2:$G$769,"Active",Assignments!$Y$2:$Y$769,"<="&F$4,Assignments!$Z$2:$Z$769,">="&F$4)) | G14: =IF($A14="","",SUMIFS(Assignments!$X$2:$X$769,Assignments!$A$2:$A$769,$A14,Assignments!$G$2:$G$769,"Active",Assignments!$V$2:$V$769,"<="&G$4,Assignments!$W$2:$W$769,">="&G$4)+SUMIFS(Assignments!$AA$2:$AA$769,Assignments!$A$2:$A$769,$A14,Assignments!$G$2:$G$769,"Active",Assignments!$Y$2:$Y$769,"<="&G$4,Assignments!$Z$2:$Z$769,">="&G$4)) | H14: =IF($A14="","",SUMIFS(Assignments!$X$2:$X$769,Assignments!$A$2:$A$769,$A14,Assignments!$G$2:$G$769,"Active",Assignments!$V$2:$V$769,"<="&H$4,Assignments!$W$2:$W$769,">="&H$4)+SUMIFS(Assignments!$AA$2:$AA$769,Assignments!$A$2:$A$769,$A14,Assignments!$G$2:$G$769,"Active",Assignments!$Y$2:$Y$769,"<="&H$4,Assignments!$Z$2:$Z$769,">="&H$4)) | I14: =IF($A14="","",SUMIFS(Assignments!$X$2:$X$769,Assignments!$A$2:$A$769,$A14,Assignments!$G$2:$G$769,"Active",Assignments!$V$2:$V$769,"<="&I$4,Assignments!$W$2:$W$769,">="&I$4)+SUMIFS(Assignments!$AA$2:$AA$769,Assignments!$A$2:$A$769,$A14,Assignments!$G$2:$G$769,"Active",Assignments!$Y$2:$Y$769,"<="&I$4,Assignments!$Z$2:$Z$769,">="&I$4)) | J14: =IF($A14="","",SUMIFS(Assignments!$X$2:$X$769,Assignments!$A$2:$A$769,$A14,Assignments!$G$2:$G$769,"Active",Assignments!$V$2:$V$769,"<="&J$4,Assignments!$W$2:$W$769,">="&J$4)+SUMIFS(Assignments!$AA$2:$AA$769,Assignments!$A$2:$A$769,$A14,Assignments!$G$2:$G$769,"Active",Assignments!$Y$2:$Y$769,"<="&J$4,Assignments!$Z$2:$Z$769,">="&J$4)) | ... AB14: =IF($A14="","",SUMIFS(Assignments!$X$2:$X$769,Assignments!$A$2:$A$769,$A14,Assignments!$G$2:$G$769,"Active",Assignments!$V$2:$V$769,"<="&AB$4,Assignments!$W$2:$W$769,">="&AB$4)+SUMIFS(Assignments!$AA$2:$AA$769,Assignments!$A$2:$A$769,$A14,Assignments!$G$2:$G$769,"Active",Assignments!$Y$2:$Y$769,"<="&AB$4,Assignments!$Z$2:$Z$769,">="&AB$4))
A15: =IF(Roster!$A12="","",Roster!$A12) | B15: =IF($A15="","",IFERROR(INDEX(Roster!$D$2:$D$40,MATCH($A15,Roster!$A$2:$A$40,0)),"")) | C15: =IF($A15="","",SUMIFS(Assignments!$X$2:$X$769,Assignments!$A$2:$A$769,$A15,Assignments!$G$2:$G$769,"Active",Assignments!$V$2:$V$769,"<="&C$4,Assignments!$W$2:$W$769,">="&C$4)+SUMIFS(Assignments!$AA$2:$AA$769,Assignments!$A$2:$A$769,$A15,Assignments!$G$2:$G$769,"Active",Assignments!$Y$2:$Y$769,"<="&C$4,Assignments!$Z$2:$Z$769,">="&C$4)) | D15: =IF($A15="","",SUMIFS(Assignments!$X$2:$X$769,Assignments!$A$2:$A$769,$A15,Assignments!$G$2:$G$769,"Active",Assignments!$V$2:$V$769,"<="&D$4,Assignments!$W$2:$W$769,">="&D$4)+SUMIFS(Assignments!$AA$2:$AA$769,Assignments!$A$2:$A$769,$A15,Assignments!$G$2:$G$769,"Active",Assignments!$Y$2:$Y$769,"<="&D$4,Assignments!$Z$2:$Z$769,">="&D$4)) | E15: =IF($A15="","",SUMIFS(Assignments!$X$2:$X$769,Assignments!$A$2:$A$769,$A15,Assignments!$G$2:$G$769,"Active",Assignments!$V$2:$V$769,"<="&E$4,Assignments!$W$2:$W$769,">="&E$4)+SUMIFS(Assignments!$AA$2:$AA$769,Assignments!$A$2:$A$769,$A15,Assignments!$G$2:$G$769,"Active",Assignments!$Y$2:$Y$769,"<="&E$4,Assignments!$Z$2:$Z$769,">="&E$4)) | F15: =IF($A15="","",SUMIFS(Assignments!$X$2:$X$769,Assignments!$A$2:$A$769,$A15,Assignments!$G$2:$G$769,"Active",Assignments!$V$2:$V$769,"<="&F$4,Assignments!$W$2:$W$769,">="&F$4)+SUMIFS(Assignments!$AA$2:$AA$769,Assignments!$A$2:$A$769,$A15,Assignments!$G$2:$G$769,"Active",Assignments!$Y$2:$Y$769,"<="&F$4,Assignments!$Z$2:$Z$769,">="&F$4)) | G15: =IF($A15="","",SUMIFS(Assignments!$X$2:$X$769,Assignments!$A$2:$A$769,$A15,Assignments!$G$2:$G$769,"Active",Assignments!$V$2:$V$769,"<="&G$4,Assignments!$W$2:$W$769,">="&G$4)+SUMIFS(Assignments!$AA$2:$AA$769,Assignments!$A$2:$A$769,$A15,Assignments!$G$2:$G$769,"Active",Assignments!$Y$2:$Y$769,"<="&G$4,Assignments!$Z$2:$Z$769,">="&G$4)) | H15: =IF($A15="","",SUMIFS(Assignments!$X$2:$X$769,Assignments!$A$2:$A$769,$A15,Assignments!$G$2:$G$769,"Active",Assignments!$V$2:$V$769,"<="&H$4,Assignments!$W$2:$W$769,">="&H$4)+SUMIFS(Assignments!$AA$2:$AA$769,Assignments!$A$2:$A$769,$A15,Assignments!$G$2:$G$769,"Active",Assignments!$Y$2:$Y$769,"<="&H$4,Assignments!$Z$2:$Z$769,">="&H$4)) | I15: =IF($A15="","",SUMIFS(Assignments!$X$2:$X$769,Assignments!$A$2:$A$769,$A15,Assignments!$G$2:$G$769,"Active",Assignments!$V$2:$V$769,"<="&I$4,Assignments!$W$2:$W$769,">="&I$4)+SUMIFS(Assignments!$AA$2:$AA$769,Assignments!$A$2:$A$769,$A15,Assignments!$G$2:$G$769,"Active",Assignments!$Y$2:$Y$769,"<="&I$4,Assignments!$Z$2:$Z$769,">="&I$4)) | J15: =IF($A15="","",SUMIFS(Assignments!$X$2:$X$769,Assignments!$A$2:$A$769,$A15,Assignments!$G$2:$G$769,"Active",Assignments!$V$2:$V$769,"<="&J$4,Assignments!$W$2:$W$769,">="&J$4)+SUMIFS(Assignments!$AA$2:$AA$769,Assignments!$A$2:$A$769,$A15,Assignments!$G$2:$G$769,"Active",Assignments!$Y$2:$Y$769,"<="&J$4,Assignments!$Z$2:$Z$769,">="&J$4)) | ... AB15: =IF($A15="","",SUMIFS(Assignments!$X$2:$X$769,Assignments!$A$2:$A$769,$A15,Assignments!$G$2:$G$769,"Active",Assignments!$V$2:$V$769,"<="&AB$4,Assignments!$W$2:$W$769,">="&AB$4)+SUMIFS(Assignments!$AA$2:$AA$769,Assignments!$A$2:$A$769,$A15,Assignments!$G$2:$G$769,"Active",Assignments!$Y$2:$Y$769,"<="&AB$4,Assignments!$Z$2:$Z$769,">="&AB$4))
A16: =IF(Roster!$A13="","",Roster!$A13) | B16: =IF($A16="","",IFERROR(INDEX(Roster!$D$2:$D$40,MATCH($A16,Roster!$A$2:$A$40,0)),"")) | C16: =IF($A16="","",SUMIFS(Assignments!$X$2:$X$769,Assignments!$A$2:$A$769,$A16,Assignments!$G$2:$G$769,"Active",Assignments!$V$2:$V$769,"<="&C$4,Assignments!$W$2:$W$769,">="&C$4)+SUMIFS(Assignments!$AA$2:$AA$769,Assignments!$A$2:$A$769,$A16,Assignments!$G$2:$G$769,"Active",Assignments!$Y$2:$Y$769,"<="&C$4,Assignments!$Z$2:$Z$769,">="&C$4)) | D16: =IF($A16="","",SUMIFS(Assignments!$X$2:$X$769,Assignments!$A$2:$A$769,$A16,Assignments!$G$2:$G$769,"Active",Assignments!$V$2:$V$769,"<="&D$4,Assignments!$W$2:$W$769,">="&D$4)+SUMIFS(Assignments!$AA$2:$AA$769,Assignments!$A$2:$A$769,$A16,Assignments!$G$2:$G$769,"Active",Assignments!$Y$2:$Y$769,"<="&D$4,Assignments!$Z$2:$Z$769,">="&D$4)) | E16: =IF($A16="","",SUMIFS(Assignments!$X$2:$X$769,Assignments!$A$2:$A$769,$A16,Assignments!$G$2:$G$769,"Active",Assignments!$V$2:$V$769,"<="&E$4,Assignments!$W$2:$W$769,">="&E$4)+SUMIFS(Assignments!$AA$2:$AA$769,Assignments!$A$2:$A$769,$A16,Assignments!$G$2:$G$769,"Active",Assignments!$Y$2:$Y$769,"<="&E$4,Assignments!$Z$2:$Z$769,">="&E$4)) | F16: =IF($A16="","",SUMIFS(Assignments!$X$2:$X$769,Assignments!$A$2:$A$769,$A16,Assignments!$G$2:$G$769,"Active",Assignments!$V$2:$V$769,"<="&F$4,Assignments!$W$2:$W$769,">="&F$4)+SUMIFS(Assignments!$AA$2:$AA$769,Assignments!$A$2:$A$769,$A16,Assignments!$G$2:$G$769,"Active",Assignments!$Y$2:$Y$769,"<="&F$4,Assignments!$Z$2:$Z$769,">="&F$4)) | G16: =IF($A16="","",SUMIFS(Assignments!$X$2:$X$769,Assignments!$A$2:$A$769,$A16,Assignments!$G$2:$G$769,"Active",Assignments!$V$2:$V$769,"<="&G$4,Assignments!$W$2:$W$769,">="&G$4)+SUMIFS(Assignments!$AA$2:$AA$769,Assignments!$A$2:$A$769,$A16,Assignments!$G$2:$G$769,"Active",Assignments!$Y$2:$Y$769,"<="&G$4,Assignments!$Z$2:$Z$769,">="&G$4)) | H16: =IF($A16="","",SUMIFS(Assignments!$X$2:$X$769,Assignments!$A$2:$A$769,$A16,Assignments!$G$2:$G$769,"Active",Assignments!$V$2:$V$769,"<="&H$4,Assignments!$W$2:$W$769,">="&H$4)+SUMIFS(Assignments!$AA$2:$AA$769,Assignments!$A$2:$A$769,$A16,Assignments!$G$2:$G$769,"Active",Assignments!$Y$2:$Y$769,"<="&H$4,Assignments!$Z$2:$Z$769,">="&H$4)) | I16: =IF($A16="","",SUMIFS(Assignments!$X$2:$X$769,Assignments!$A$2:$A$769,$A16,Assignments!$G$2:$G$769,"Active",Assignments!$V$2:$V$769,"<="&I$4,Assignments!$W$2:$W$769,">="&I$4)+SUMIFS(Assignments!$AA$2:$AA$769,Assignments!$A$2:$A$769,$A16,Assignments!$G$2:$G$769,"Active",Assignments!$Y$2:$Y$769,"<="&I$4,Assignments!$Z$2:$Z$769,">="&I$4)) | J16: =IF($A16="","",SUMIFS(Assignments!$X$2:$X$769,Assignments!$A$2:$A$769,$A16,Assignments!$G$2:$G$769,"Active",Assignments!$V$2:$V$769,"<="&J$4,Assignments!$W$2:$W$769,">="&J$4)+SUMIFS(Assignments!$AA$2:$AA$769,Assignments!$A$2:$A$769,$A16,Assignments!$G$2:$G$769,"Active",Assignments!$Y$2:$Y$769,"<="&J$4,Assignments!$Z$2:$Z$769,">="&J$4)) | ... AB16: =IF($A16="","",SUMIFS(Assignments!$X$2:$X$769,Assignments!$A$2:$A$769,$A16,Assignments!$G$2:$G$769,"Active",Assignments!$V$2:$V$769,"<="&AB$4,Assignments!$W$2:$W$769,">="&AB$4)+SUMIFS(Assignments!$AA$2:$AA$769,Assignments!$A$2:$A$769,$A16,Assignments!$G$2:$G$769,"Active",Assignments!$Y$2:$Y$769,"<="&AB$4,Assignments!$Z$2:$Z$769,">="&AB$4))
... A43: =IF(Roster!$A40="","",Roster!$A40) | B43: =IF($A43="","",IFERROR(INDEX(Roster!$D$2:$D$40,MATCH($A43,Roster!$A$2:$A$40,0)),"")) | C43: =IF($A43="","",SUMIFS(Assignments!$X$2:$X$769,Assignments!$A$2:$A$769,$A43,Assignments!$G$2:$G$769,"Active",Assignments!$V$2:$V$769,"<="&C$4,Assignments!$W$2:$W$769,">="&C$4)+SUMIFS(Assignments!$AA$2:$AA$769,Assignments!$A$2:$A$769,$A43,Assignments!$G$2:$G$769,"Active",Assignments!$Y$2:$Y$769,"<="&C$4,Assignments!$Z$2:$Z$769,">="&C$4)) | D43: =IF($A43="","",SUMIFS(Assignments!$X$2:$X$769,Assignments!$A$2:$A$769,$A43,Assignments!$G$2:$G$769,"Active",Assignments!$V$2:$V$769,"<="&D$4,Assignments!$W$2:$W$769,">="&D$4)+SUMIFS(Assignments!$AA$2:$AA$769,Assignments!$A$2:$A$769,$A43,Assignments!$G$2:$G$769,"Active",Assignments!$Y$2:$Y$769,"<="&D$4,Assignments!$Z$2:$Z$769,">="&D$4)) | E43: =IF($A43="","",SUMIFS(Assignments!$X$2:$X$769,Assignments!$A$2:$A$769,$A43,Assignments!$G$2:$G$769,"Active",Assignments!$V$2:$V$769,"<="&E$4,Assignments!$W$2:$W$769,">="&E$4)+SUMIFS(Assignments!$AA$2:$AA$769,Assignments!$A$2:$A$769,$A43,Assignments!$G$2:$G$769,"Active",Assignments!$Y$2:$Y$769,"<="&E$4,Assignments!$Z$2:$Z$769,">="&E$4)) | F43: =IF($A43="","",SUMIFS(Assignments!$X$2:$X$769,Assignments!$A$2:$A$769,$A43,Assignments!$G$2:$G$769,"Active",Assignments!$V$2:$V$769,"<="&F$4,Assignments!$W$2:$W$769,">="&F$4)+SUMIFS(Assignments!$AA$2:$AA$769,Assignments!$A$2:$A$769,$A43,Assignments!$G$2:$G$769,"Active",Assignments!$Y$2:$Y$769,"<="&F$4,Assignments!$Z$2:$Z$769,">="&F$4)) | G43: =IF($A43="","",SUMIFS(Assignments!$X$2:$X$769,Assignments!$A$2:$A$769,$A43,Assignments!$G$2:$G$769,"Active",Assignments!$V$2:$V$769,"<="&G$4,Assignments!$W$2:$W$769,">="&G$4)+SUMIFS(Assignments!$AA$2:$AA$769,Assignments!$A$2:$A$769,$A43,Assignments!$G$2:$G$769,"Active",Assignments!$Y$2:$Y$769,"<="&G$4,Assignments!$Z$2:$Z$769,">="&G$4)) | H43: =IF($A43="","",SUMIFS(Assignments!$X$2:$X$769,Assignments!$A$2:$A$769,$A43,Assignments!$G$2:$G$769,"Active",Assignments!$V$2:$V$769,"<="&H$4,Assignments!$W$2:$W$769,">="&H$4)+SUMIFS(Assignments!$AA$2:$AA$769,Assignments!$A$2:$A$769,$A43,Assignments!$G$2:$G$769,"Active",Assignments!$Y$2:$Y$769,"<="&H$4,Assignments!$Z$2:$Z$769,">="&H$4)) | I43: =IF($A43="","",SUMIFS(Assignments!$X$2:$X$769,Assignments!$A$2:$A$769,$A43,Assignments!$G$2:$G$769,"Active",Assignments!$V$2:$V$769,"<="&I$4,Assignments!$W$2:$W$769,">="&I$4)+SUMIFS(Assignments!$AA$2:$AA$769,Assignments!$A$2:$A$769,$A43,Assignments!$G$2:$G$769,"Active",Assignments!$Y$2:$Y$769,"<="&I$4,Assignments!$Z$2:$Z$769,">="&I$4)) | J43: =IF($A43="","",SUMIFS(Assignments!$X$2:$X$769,Assignments!$A$2:$A$769,$A43,Assignments!$G$2:$G$769,"Active",Assignments!$V$2:$V$769,"<="&J$4,Assignments!$W$2:$W$769,">="&J$4)+SUMIFS(Assignments!$AA$2:$AA$769,Assignments!$A$2:$A$769,$A43,Assignments!$G$2:$G$769,"Active",Assignments!$Y$2:$Y$769,"<="&J$4,Assignments!$Z$2:$Z$769,">="&J$4)) | ... AB43: =IF($A43="","",SUMIFS(Assignments!$X$2:$X$769,Assignments!$A$2:$A$769,$A43,Assignments!$G$2:$G$769,"Active",Assignments!$V$2:$V$769,"<="&AB$4,Assignments!$W$2:$W$769,">="&AB$4)+SUMIFS(Assignments!$AA$2:$AA$769,Assignments!$A$2:$A$769,$A43,Assignments!$G$2:$G$769,"Active",Assignments!$Y$2:$Y$769,"<="&AB$4,Assignments!$Z$2:$Z$769,">="&AB$4))
A45: Team planned | C45: =SUM(C5:C43) | D45: =SUM(D5:D43) | E45: =SUM(E5:E43) | F45: =SUM(F5:F43) | G45: =SUM(G5:G43) | H45: =SUM(H5:H43) | I45: =SUM(I5:I43) | J45: =SUM(J5:J43) | ... AB45: =SUM(AB5:AB43)
A46: Team capacity | C46: =SUM(Roster!$D$2:$D$40) | D46: =SUM(Roster!$D$2:$D$40) | E46: =SUM(Roster!$D$2:$D$40) | F46: =SUM(Roster!$D$2:$D$40) | G46: =SUM(Roster!$D$2:$D$40) | H46: =SUM(Roster!$D$2:$D$40) | I46: =SUM(Roster!$D$2:$D$40) | J46: =SUM(Roster!$D$2:$D$40) | ... AB46: =SUM(Roster!$D$2:$D$40)
A47: Headroom | C47: =C46-C45 | D47: =D46-D45 | E47: =E46-E45 | F47: =F46-F45 | G47: =G46-G45 | H47: =H46-H45 | I47: =I46-I45 | J47: =J46-J45 | ... AB47: =AB46-AB45

Sheet Check-in
A1: Weekly Check-in Agenda
A2: ="As of "&TEXT(Settings!$B$19,"yyyy-mm-dd")&" | Validate near-term capacity, rebalance workload, confirm staffing on incoming deals. Update Settings!B19 to today before each check-in."
A3: Definitions (adjust in Settings if the team means something different): 'Missing level' = the deal has an Effort archetype that expects hours from a level, but nobody at that level is actively staffed. 'Stale' = weeks since Added-on >= the Settings threshold (currently editable at Settings!B20).
A5: 1) Capacity - next 4 weeks
A6: Person | B6: Level | C6: Cap hrs/wk | D6: Max load (4 wk) | E6: Max utilization | F6: Flag
A7: =IF(Roster!$A2="","",Roster!$A2) | B7: =IF($A7="","",Roster!$B2) | C7: =IF($A7="","",Roster!$D2) | D7: =IF($A7="","",MAX(Capacity!$C$5:$F$5)) | E7: =IF(OR($A7="",$C7=0),"",$D7/$C7) | F7: =IF($A7="","",IF(AND(ISNUMBER($E7),$E7>1),"OVER-ALLOCATED",IF(AND(ISNUMBER($E7),$E7<0.5),"UNDER-UTILIZED","")))
A8: =IF(Roster!$A3="","",Roster!$A3) | B8: =IF($A8="","",Roster!$B3) | C8: =IF($A8="","",Roster!$D3) | D8: =IF($A8="","",MAX(Capacity!$C$6:$F$6)) | E8: =IF(OR($A8="",$C8=0),"",$D8/$C8) | F8: =IF($A8="","",IF(AND(ISNUMBER($E8),$E8>1),"OVER-ALLOCATED",IF(AND(ISNUMBER($E8),$E8<0.5),"UNDER-UTILIZED","")))
A9: =IF(Roster!$A4="","",Roster!$A4) | B9: =IF($A9="","",Roster!$B4) | C9: =IF($A9="","",Roster!$D4) | D9: =IF($A9="","",MAX(Capacity!$C$7:$F$7)) | E9: =IF(OR($A9="",$C9=0),"",$D9/$C9) | F9: =IF($A9="","",IF(AND(ISNUMBER($E9),$E9>1),"OVER-ALLOCATED",IF(AND(ISNUMBER($E9),$E9<0.5),"UNDER-UTILIZED","")))
A10: =IF(Roster!$A5="","",Roster!$A5) | B10: =IF($A10="","",Roster!$B5) | C10: =IF($A10="","",Roster!$D5) | D10: =IF($A10="","",MAX(Capacity!$C$8:$F$8)) | E10: =IF(OR($A10="",$C10=0),"",$D10/$C10) | F10: =IF($A10="","",IF(AND(ISNUMBER($E10),$E10>1),"OVER-ALLOCATED",IF(AND(ISNUMBER($E10),$E10<0.5),"UNDER-UTILIZED","")))
A11: =IF(Roster!$A6="","",Roster!$A6) | B11: =IF($A11="","",Roster!$B6) | C11: =IF($A11="","",Roster!$D6) | D11: =IF($A11="","",MAX(Capacity!$C$9:$F$9)) | E11: =IF(OR($A11="",$C11=0),"",$D11/$C11) | F11: =IF($A11="","",IF(AND(ISNUMBER($E11),$E11>1),"OVER-ALLOCATED",IF(AND(ISNUMBER($E11),$E11<0.5),"UNDER-UTILIZED","")))
A12: =IF(Roster!$A7="","",Roster!$A7) | B12: =IF($A12="","",Roster!$B7) | C12: =IF($A12="","",Roster!$D7) | D12: =IF($A12="","",MAX(Capacity!$C$10:$F$10)) | E12: =IF(OR($A12="",$C12=0),"",$D12/$C12) | F12: =IF($A12="","",IF(AND(ISNUMBER($E12),$E12>1),"OVER-ALLOCATED",IF(AND(ISNUMBER($E12),$E12<0.5),"UNDER-UTILIZED","")))
A13: =IF(Roster!$A8="","",Roster!$A8) | B13: =IF($A13="","",Roster!$B8) | C13: =IF($A13="","",Roster!$D8) | D13: =IF($A13="","",MAX(Capacity!$C$11:$F$11)) | E13: =IF(OR($A13="",$C13=0),"",$D13/$C13) | F13: =IF($A13="","",IF(AND(ISNUMBER($E13),$E13>1),"OVER-ALLOCATED",IF(AND(ISNUMBER($E13),$E13<0.5),"UNDER-UTILIZED","")))
A14: =IF(Roster!$A9="","",Roster!$A9) | B14: =IF($A14="","",Roster!$B9) | C14: =IF($A14="","",Roster!$D9) | D14: =IF($A14="","",MAX(Capacity!$C$12:$F$12)) | E14: =IF(OR($A14="",$C14=0),"",$D14/$C14) | F14: =IF($A14="","",IF(AND(ISNUMBER($E14),$E14>1),"OVER-ALLOCATED",IF(AND(ISNUMBER($E14),$E14<0.5),"UNDER-UTILIZED","")))
A15: =IF(Roster!$A10="","",Roster!$A10) | B15: =IF($A15="","",Roster!$B10) | C15: =IF($A15="","",Roster!$D10) | D15: =IF($A15="","",MAX(Capacity!$C$13:$F$13)) | E15: =IF(OR($A15="",$C15=0),"",$D15/$C15) | F15: =IF($A15="","",IF(AND(ISNUMBER($E15),$E15>1),"OVER-ALLOCATED",IF(AND(ISNUMBER($E15),$E15<0.5),"UNDER-UTILIZED","")))
A16: =IF(Roster!$A11="","",Roster!$A11) | B16: =IF($A16="","",Roster!$B11) | C16: =IF($A16="","",Roster!$D11) | D16: =IF($A16="","",MAX(Capacity!$C$14:$F$14)) | E16: =IF(OR($A16="",$C16=0),"",$D16/$C16) | F16: =IF($A16="","",IF(AND(ISNUMBER($E16),$E16>1),"OVER-ALLOCATED",IF(AND(ISNUMBER($E16),$E16<0.5),"UNDER-UTILIZED","")))
A17: =IF(Roster!$A12="","",Roster!$A12) | B17: =IF($A17="","",Roster!$B12) | C17: =IF($A17="","",Roster!$D12) | D17: =IF($A17="","",MAX(Capacity!$C$15:$F$15)) | E17: =IF(OR($A17="",$C17=0),"",$D17/$C17) | F17: =IF($A17="","",IF(AND(ISNUMBER($E17),$E17>1),"OVER-ALLOCATED",IF(AND(ISNUMBER($E17),$E17<0.5),"UNDER-UTILIZED","")))
A18: =IF(Roster!$A13="","",Roster!$A13) | B18: =IF($A18="","",Roster!$B13) | C18: =IF($A18="","",Roster!$D13) | D18: =IF($A18="","",MAX(Capacity!$C$16:$F$16)) | E18: =IF(OR($A18="",$C18=0),"",$D18/$C18) | F18: =IF($A18="","",IF(AND(ISNUMBER($E18),$E18>1),"OVER-ALLOCATED",IF(AND(ISNUMBER($E18),$E18<0.5),"UNDER-UTILIZED","")))
A19: =IF(Roster!$A14="","",Roster!$A14) | B19: =IF($A19="","",Roster!$B14) | C19: =IF($A19="","",Roster!$D14) | D19: =IF($A19="","",MAX(Capacity!$C$17:$F$17)) | E19: =IF(OR($A19="",$C19=0),"",$D19/$C19) | F19: =IF($A19="","",IF(AND(ISNUMBER($E19),$E19>1),"OVER-ALLOCATED",IF(AND(ISNUMBER($E19),$E19<0.5),"UNDER-UTILIZED","")))
A20: =IF(Roster!$A15="","",Roster!$A15) | B20: =IF($A20="","",Roster!$B15) | C20: =IF($A20="","",Roster!$D15) | D20: =IF($A20="","",MAX(Capacity!$C$18:$F$18)) | E20: =IF(OR($A20="",$C20=0),"",$D20/$C20) | F20: =IF($A20="","",IF(AND(ISNUMBER($E20),$E20>1),"OVER-ALLOCATED",IF(AND(ISNUMBER($E20),$E20<0.5),"UNDER-UTILIZED","")))
A21: =IF(Roster!$A16="","",Roster!$A16) | B21: =IF($A21="","",Roster!$B16) | C21: =IF($A21="","",Roster!$D16) | D21: =IF($A21="","",MAX(Capacity!$C$19:$F$19)) | E21: =IF(OR($A21="",$C21=0),"",$D21/$C21) | F21: =IF($A21="","",IF(AND(ISNUMBER($E21),$E21>1),"OVER-ALLOCATED",IF(AND(ISNUMBER($E21),$E21<0.5),"UNDER-UTILIZED","")))
A22: =IF(Roster!$A17="","",Roster!$A17) | B22: =IF($A22="","",Roster!$B17) | C22: =IF($A22="","",Roster!$D17) | D22: =IF($A22="","",MAX(Capacity!$C$20:$F$20)) | E22: =IF(OR($A22="",$C22=0),"",$D22/$C22) | F22: =IF($A22="","",IF(AND(ISNUMBER($E22),$E22>1),"OVER-ALLOCATED",IF(AND(ISNUMBER($E22),$E22<0.5),"UNDER-UTILIZED","")))
A23: =IF(Roster!$A18="","",Roster!$A18) | B23: =IF($A23="","",Roster!$B18) | C23: =IF($A23="","",Roster!$D18) | D23: =IF($A23="","",MAX(Capacity!$C$21:$F$21)) | E23: =IF(OR($A23="",$C23=0),"",$D23/$C23) | F23: =IF($A23="","",IF(AND(ISNUMBER($E23),$E23>1),"OVER-ALLOCATED",IF(AND(ISNUMBER($E23),$E23<0.5),"UNDER-UTILIZED","")))
A24: =IF(Roster!$A19="","",Roster!$A19) | B24: =IF($A24="","",Roster!$B19) | C24: =IF($A24="","",Roster!$D19) | D24: =IF($A24="","",MAX(Capacity!$C$22:$F$22)) | E24: =IF(OR($A24="",$C24=0),"",$D24/$C24) | F24: =IF($A24="","",IF(AND(ISNUMBER($E24),$E24>1),"OVER-ALLOCATED",IF(AND(ISNUMBER($E24),$E24<0.5),"UNDER-UTILIZED","")))
A25: =IF(Roster!$A20="","",Roster!$A20) | B25: =IF($A25="","",Roster!$B20) | C25: =IF($A25="","",Roster!$D20) | D25: =IF($A25="","",MAX(Capacity!$C$23:$F$23)) | E25: =IF(OR($A25="",$C25=0),"",$D25/$C25) | F25: =IF($A25="","",IF(AND(ISNUMBER($E25),$E25>1),"OVER-ALLOCATED",IF(AND(ISNUMBER($E25),$E25<0.5),"UNDER-UTILIZED","")))
A26: =IF(Roster!$A21="","",Roster!$A21) | B26: =IF($A26="","",Roster!$B21) | C26: =IF($A26="","",Roster!$D21) | D26: =IF($A26="","",MAX(Capacity!$C$24:$F$24)) | E26: =IF(OR($A26="",$C26=0),"",$D26/$C26) | F26: =IF($A26="","",IF(AND(ISNUMBER($E26),$E26>1),"OVER-ALLOCATED",IF(AND(ISNUMBER($E26),$E26<0.5),"UNDER-UTILIZED","")))
A27: =IF(Roster!$A22="","",Roster!$A22) | B27: =IF($A27="","",Roster!$B22) | C27: =IF($A27="","",Roster!$D22) | D27: =IF($A27="","",MAX(Capacity!$C$25:$F$25)) | E27: =IF(OR($A27="",$C27=0),"",$D27/$C27) | F27: =IF($A27="","",IF(AND(ISNUMBER($E27),$E27>1),"OVER-ALLOCATED",IF(AND(ISNUMBER($E27),$E27<0.5),"UNDER-UTILIZED","")))
A28: =IF(Roster!$A23="","",Roster!$A23) | B28: =IF($A28="","",Roster!$B23) | C28: =IF($A28="","",Roster!$D23) | D28: =IF($A28="","",MAX(Capacity!$C$26:$F$26)) | E28: =IF(OR($A28="",$C28=0),"",$D28/$C28) | F28: =IF($A28="","",IF(AND(ISNUMBER($E28),$E28>1),"OVER-ALLOCATED",IF(AND(ISNUMBER($E28),$E28<0.5),"UNDER-UTILIZED","")))
A29: =IF(Roster!$A24="","",Roster!$A24) | B29: =IF($A29="","",Roster!$B24) | C29: =IF($A29="","",Roster!$D24) | D29: =IF($A29="","",MAX(Capacity!$C$27:$F$27)) | E29: =IF(OR($A29="",$C29=0),"",$D29/$C29) | F29: =IF($A29="","",IF(AND(ISNUMBER($E29),$E29>1),"OVER-ALLOCATED",IF(AND(ISNUMBER($E29),$E29<0.5),"UNDER-UTILIZED","")))
A30: =IF(Roster!$A25="","",Roster!$A25) | B30: =IF($A30="","",Roster!$B25) | C30: =IF($A30="","",Roster!$D25) | D30: =IF($A30="","",MAX(Capacity!$C$28:$F$28)) | E30: =IF(OR($A30="",$C30=0),"",$D30/$C30) | F30: =IF($A30="","",IF(AND(ISNUMBER($E30),$E30>1),"OVER-ALLOCATED",IF(AND(ISNUMBER($E30),$E30<0.5),"UNDER-UTILIZED","")))
A31: =IF(Roster!$A26="","",Roster!$A26) | B31: =IF($A31="","",Roster!$B26) | C31: =IF($A31="","",Roster!$D26) | D31: =IF($A31="","",MAX(Capacity!$C$29:$F$29)) | E31: =IF(OR($A31="",$C31=0),"",$D31/$C31) | F31: =IF($A31="","",IF(AND(ISNUMBER($E31),$E31>1),"OVER-ALLOCATED",IF(AND(ISNUMBER($E31),$E31<0.5),"UNDER-UTILIZED","")))
A32: =IF(Roster!$A27="","",Roster!$A27) | B32: =IF($A32="","",Roster!$B27) | C32: =IF($A32="","",Roster!$D27) | D32: =IF($A32="","",MAX(Capacity!$C$30:$F$30)) | E32: =IF(OR($A32="",$C32=0),"",$D32/$C32) | F32: =IF($A32="","",IF(AND(ISNUMBER($E32),$E32>1),"OVER-ALLOCATED",IF(AND(ISNUMBER($E32),$E32<0.5),"UNDER-UTILIZED","")))
A33: =IF(Roster!$A28="","",Roster!$A28) | B33: =IF($A33="","",Roster!$B28) | C33: =IF($A33="","",Roster!$D28) | D33: =IF($A33="","",MAX(Capacity!$C$31:$F$31)) | E33: =IF(OR($A33="",$C33=0),"",$D33/$C33) | F33: =IF($A33="","",IF(AND(ISNUMBER($E33),$E33>1),"OVER-ALLOCATED",IF(AND(ISNUMBER($E33),$E33<0.5),"UNDER-UTILIZED","")))
A34: =IF(Roster!$A29="","",Roster!$A29) | B34: =IF($A34="","",Roster!$B29) | C34: =IF($A34="","",Roster!$D29) | D34: =IF($A34="","",MAX(Capacity!$C$32:$F$32)) | E34: =IF(OR($A34="",$C34=0),"",$D34/$C34) | F34: =IF($A34="","",IF(AND(ISNUMBER($E34),$E34>1),"OVER-ALLOCATED",IF(AND(ISNUMBER($E34),$E34<0.5),"UNDER-UTILIZED","")))
A35: =IF(Roster!$A30="","",Roster!$A30) | B35: =IF($A35="","",Roster!$B30) | C35: =IF($A35="","",Roster!$D30) | D35: =IF($A35="","",MAX(Capacity!$C$33:$F$33)) | E35: =IF(OR($A35="",$C35=0),"",$D35/$C35) | F35: =IF($A35="","",IF(AND(ISNUMBER($E35),$E35>1),"OVER-ALLOCATED",IF(AND(ISNUMBER($E35),$E35<0.5),"UNDER-UTILIZED","")))
A36: =IF(Roster!$A31="","",Roster!$A31) | B36: =IF($A36="","",Roster!$B31) | C36: =IF($A36="","",Roster!$D31) | D36: =IF($A36="","",MAX(Capacity!$C$34:$F$34)) | E36: =IF(OR($A36="",$C36=0),"",$D36/$C36) | F36: =IF($A36="","",IF(AND(ISNUMBER($E36),$E36>1),"OVER-ALLOCATED",IF(AND(ISNUMBER($E36),$E36<0.5),"UNDER-UTILIZED","")))
A37: =IF(Roster!$A32="","",Roster!$A32) | B37: =IF($A37="","",Roster!$B32) | C37: =IF($A37="","",Roster!$D32) | D37: =IF($A37="","",MAX(Capacity!$C$35:$F$35)) | E37: =IF(OR($A37="",$C37=0),"",$D37/$C37) | F37: =IF($A37="","",IF(AND(ISNUMBER($E37),$E37>1),"OVER-ALLOCATED",IF(AND(ISNUMBER($E37),$E37<0.5),"UNDER-UTILIZED","")))
A38: =IF(Roster!$A33="","",Roster!$A33) | B38: =IF($A38="","",Roster!$B33) | C38: =IF($A38="","",Roster!$D33) | D38: =IF($A38="","",MAX(Capacity!$C$36:$F$36)) | E38: =IF(OR($A38="",$C38=0),"",$D38/$C38) | F38: =IF($A38="","",IF(AND(ISNUMBER($E38),$E38>1),"OVER-ALLOCATED",IF(AND(ISNUMBER($E38),$E38<0.5),"UNDER-UTILIZED","")))
A39: =IF(Roster!$A34="","",Roster!$A34) | B39: =IF($A39="","",Roster!$B34) | C39: =IF($A39="","",Roster!$D34) | D39: =IF($A39="","",MAX(Capacity!$C$37:$F$37)) | E39: =IF(OR($A39="",$C39=0),"",$D39/$C39) | F39: =IF($A39="","",IF(AND(ISNUMBER($E39),$E39>1),"OVER-ALLOCATED",IF(AND(ISNUMBER($E39),$E39<0.5),"UNDER-UTILIZED","")))
A40: =IF(Roster!$A35="","",Roster!$A35) | B40: =IF($A40="","",Roster!$B35) | C40: =IF($A40="","",Roster!$D35) | D40: =IF($A40="","",MAX(Capacity!$C$38:$F$38)) | E40: =IF(OR($A40="",$C40=0),"",$D40/$C40) | F40: =IF($A40="","",IF(AND(ISNUMBER($E40),$E40>1),"OVER-ALLOCATED",IF(AND(ISNUMBER($E40),$E40<0.5),"UNDER-UTILIZED","")))
A41: =IF(Roster!$A36="","",Roster!$A36) | B41: =IF($A41="","",Roster!$B36) | C41: =IF($A41="","",Roster!$D36) | D41: =IF($A41="","",MAX(Capacity!$C$39:$F$39)) | E41: =IF(OR($A41="",$C41=0),"",$D41/$C41) | F41: =IF($A41="","",IF(AND(ISNUMBER($E41),$E41>1),"OVER-ALLOCATED",IF(AND(ISNUMBER($E41),$E41<0.5),"UNDER-UTILIZED","")))
...

Sheet Scenario
A1: Scenario analysis - what-if, without touching the live plan
A2: This mirrors Capacity but applies the SCENARIO overrides you set on the Deals tab (the violet columns: Scenario probability / start / end). Leave them blank and this equals Live exactly (every Change below is 0). Fill an override - e.g. bump three proposals to 100% - to see who would blow up. The live Capacity and Check-in tabs are never affected.
A4: 1) Impact summary - who changes under the scenario (peak over the next 4 weeks)
A5: Person | B5: Cap hrs/wk | C5: Live peak | D5: Scenario peak | E5: Change | F5: Scenario util | G5: Flag
A6: =IF(Roster!$A2="","",Roster!$A2) | B6: =IF($A6="","",Roster!$D2) | C6: =IF($A6="","",MAX(Capacity!$C5:$F5)) | D6: =IF($A6="","",MAX($C48:$F48)) | E6: =IF($A6="","",$D6-$C6) | F6: =IF(OR($A6="",$B6=0),"",$D6/$B6) | G6: =IF($B6=0,"",IF(AND($D6>$B6,$C6<=$B6),"NEWLY OVER",IF($D6>$B6,"over",IF(AND($C6>$B6,$D6<=$B6),"eased",""))))
A7: =IF(Roster!$A3="","",Roster!$A3) | B7: =IF($A7="","",Roster!$D3) | C7: =IF($A7="","",MAX(Capacity!$C6:$F6)) | D7: =IF($A7="","",MAX($C49:$F49)) | E7: =IF($A7="","",$D7-$C7) | F7: =IF(OR($A7="",$B7=0),"",$D7/$B7) | G7: =IF($B7=0,"",IF(AND($D7>$B7,$C7<=$B7),"NEWLY OVER",IF($D7>$B7,"over",IF(AND($C7>$B7,$D7<=$B7),"eased",""))))
